Workbook

Sheet Current
A1: exception | B1: Count | C1: LastWeekAverage | D1: Category | E1: Review Comments | F1: trim 255 for vloopup
C2: =IFERROR(ROUNDUP(VLOOKUP(F2,'30Days-Baseline'!C:D,2,FALSE),0),"NotExist") -> NotExist | D2: =IFERROR(IF(B2>ROUNDUP(C2,0),"Elevated","Ok"),"New") -> New | E2: =VLOOKUP(A:A,Reviewed!B:C,2,0) -> #N/A | F2: =LEFT(A2,255)
C3: =IFERROR(ROUNDUP(VLOOKUP(F3,'30Days-Baseline'!C:D,2,FALSE),0),"NotExist") -> NotExist | D3: =IFERROR(IF(B3>ROUNDUP(C3,0),"Elevated","Ok"),"New") -> New | E3: =VLOOKUP(A:A,Reviewed!B:C,2,0) -> #N/A | F3: =LEFT(A3,255)
C4: =IFERROR(ROUNDUP(VLOOKUP(F4,'30Days-Baseline'!C:D,2,FALSE),0),"NotExist") -> NotExist | D4: =IFERROR(IF(B4>ROUNDUP(C4,0),"Elevated","Ok"),"New") -> New | E4: =VLOOKUP(A:A,Reviewed!B:C,2,0) -> #N/A | F4: =LEFT(A4,255)
C5: =IFERROR(ROUNDUP(VLOOKUP(F5,'30Days-Baseline'!C:D,2,FALSE),0),"NotExist") -> NotExist | D5: =IFERROR(IF(B5>ROUNDUP(C5,0),"Elevated","Ok"),"New") -> New | E5: =VLOOKUP(A:A,Reviewed!B:C,2,0) -> #N/A | F5: =LEFT(A5,255)
C6: =IFERROR(ROUNDUP(VLOOKUP(F6,'30Days-Baseline'!C:D,2,FALSE),0),"NotExist") -> NotExist | D6: =IFERROR(IF(B6>ROUNDUP(C6,0),"Elevated","Ok"),"New") -> New | E6: =VLOOKUP(A:A,Reviewed!B:C,2,0) -> #N/A | F6: =LEFT(A6,255)
C7: =IFERROR(ROUNDUP(VLOOKUP(F7,'30Days-Baseline'!C:D,2,FALSE),0),"NotExist") -> NotExist | D7: =IFERROR(IF(B7>ROUNDUP(C7,0),"Elevated","Ok"),"New") -> New | E7: =VLOOKUP(A:A,Reviewed!B:C,2,0) -> #N/A | F7: =LEFT(A7,255)
C8: =IFERROR(ROUNDUP(VLOOKUP(F8,'30Days-Baseline'!C:D,2,FALSE),0),"NotExist") -> NotExist | D8: =IFERROR(IF(B8>ROUNDUP(C8,0),"Elevated","Ok"),"New") -> New | E8: =VLOOKUP(A:A,Reviewed!B:C,2,0) -> #N/A | F8: =LEFT(A8,255)
C9: =IFERROR(ROUNDUP(VLOOKUP(F9,'30Days-Baseline'!C:D,2,FALSE),0),"NotExist") -> NotExist | D9: =IFERROR(IF(B9>ROUNDUP(C9,0),"Elevated","Ok"),"New") -> New | E9: =VLOOKUP(A:A,Reviewed!B:C,2,0) -> #N/A | F9: =LEFT(A9,255)
C10: =IFERROR(ROUNDUP(VLOOKUP(F10,'30Days-Baseline'!C:D,2,FALSE),0),"NotExist") -> NotExist | D10: =IFERROR(IF(B10>ROUNDUP(C10,0),"Elevated","Ok"),"New") -> New | E10: =VLOOKUP(A:A,Reviewed!B:C,2,0) -> #N/A | F10: =LEFT(A10,255)
C11: =IFERROR(ROUNDUP(VLOOKUP(F11,'30Days-Baseline'!C:D,2,FALSE),0),"NotExist") -> NotExist | D11: =IFERROR(IF(B11>ROUNDUP(C11,0),"Elevated","Ok"),"New") -> New | E11: =VLOOKUP(A:A,Reviewed!B:C,2,0) -> #N/A | F11: =LEFT(A11,255)
C12: =IFERROR(ROUNDUP(VLOOKUP(F12,'30Days-Baseline'!C:D,2,FALSE),0),"NotExist") -> NotExist | D12: =IFERROR(IF(B12>ROUNDUP(C12,0),"Elevated","Ok"),"New") -> New | E12: =VLOOKUP(A:A,Reviewed!B:C,2,0) -> #N/A | F12: =LEFT(A12,255)
C13: =IFERROR(ROUNDUP(VLOOKUP(F13,'30Days-Baseline'!C:D,2,FALSE),0),"NotExist") -> NotExist | D13: =IFERROR(IF(B13>ROUNDUP(C13,0),"Elevated","Ok"),"New") -> New | E13: =VLOOKUP(A:A,Reviewed!B:C,2,0) -> #N/A | F13: =LEFT(A13,255)
... C181: =IFERROR(ROUNDUP(VLOOKUP(F181,'30Days-Baseline'!C:D,2,FALSE),0),"NotExist") -> NotExist | D181: =IFERROR(IF(B181>ROUNDUP(C181,0),"Elevated","Ok"),"New") -> New | E181: =VLOOKUP(A:A,Reviewed!B:C,2,0) -> #N/A | F181: =LEFT(A181,255)
C182: =IFERROR(ROUNDUP(VLOOKUP(F182,'30Days-Baseline'!C:D,2,FALSE),0),"NotExist") -> NotExist | D182: =IFERROR(IF(B182>ROUNDUP(C182,0),"Elevated","Ok"),"New") -> New | E182: =VLOOKUP(A:A,Reviewed!B:C,2,0) -> #N/A
C183: =IFERROR(ROUNDUP(VLOOKUP(F183,'30Days-Baseline'!C:D,2,FALSE),0),"NotExist") -> NotExist | D183: =IFERROR(IF(B183>ROUNDUP(C183,0),"Elevated","Ok"),"New") -> New | E183: =VLOOKUP(A:A,Reviewed!B:C,2,0) -> #N/A
C184: =IFERROR(ROUNDUP(VLOOKUP(F184,'30Days-Baseline'!C:D,2,FALSE),0),"NotExist") -> NotExist | D184: =IFERROR(IF(B184>ROUNDUP(C184,0),"Elevated","Ok"),"New") -> New | E184: =VLOOKUP(A:A,Reviewed!B:C,2,0) -> #N/A
C185: =IFERROR(ROUNDUP(VLOOKUP(F185,'30Days-Baseline'!C:D,2,FALSE),0),"NotExist") -> NotExist | D185: =IFERROR(IF(B185>ROUNDUP(C185,0),"Elevated","Ok"),"New") -> New | E185: =VLOOKUP(A:A,Reviewed!B:C,2,0) -> #N/A
C186: =IFERROR(ROUNDUP(VLOOKUP(F186,'30Days-Baseline'!C:D,2,FALSE),0),"NotExist") -> NotExist | D186: =IFERROR(IF(B186>ROUNDUP(C186,0),"Elevated","Ok"),"New") -> New | E186: =VLOOKUP(A:A,Reviewed!B:C,2,0) -> #N/A | F186: =LEFT(A186,255)
C187: =IFERROR(ROUNDUP(VLOOKUP(F187,'30Days-Baseline'!C:D,2,FALSE),0),"NotExist") -> NotExist | D187: =IFERROR(IF(B187>ROUNDUP(C187,0),"Elevated","Ok"),"New") -> New | E187: =VLOOKUP(A:A,Reviewed!B:C,2,0) -> #N/A | F187: =LEFT(A187,255)
C188: =IFERROR(ROUNDUP(VLOOKUP(F188,'30Days-Baseline'!C:D,2,FALSE),0),"NotExist") -> NotExist | D188: =IFERROR(IF(B188>ROUNDUP(C188,0),"Elevated","Ok"),"New") -> New | E188: =VLOOKUP(A:A,Reviewed!B:C,2,0) -> #N/A | F188: =LEFT(A188,255)
C189: =IFERROR(ROUNDUP(VLOOKUP(F189,'30Days-Baseline'!C:D,2,FALSE),0),"NotExist") -> NotExist | D189: =IFERROR(IF(B189>ROUNDUP(C189,0),"Elevated","Ok"),"New") -> New | E189: =VLOOKUP(A:A,Reviewed!B:C,2,0) -> #N/A | F189: =LEFT(A189,255)
C190: =IFERROR(ROUNDUP(VLOOKUP(F190,'30Days-Baseline'!C:D,2,FALSE),0),"NotExist") -> NotExist | D190: =IFERROR(IF(B190>ROUNDUP(C190,0),"Elevated","Ok"),"New") -> New | E190: =VLOOKUP(A:A,Reviewed!B:C,2,0) -> #N/A | F190: =LEFT(A190,255)
C191: =IFERROR(ROUNDUP(VLOOKUP(F191,'30Days-Baseline'!C:D,2,FALSE),0),"NotExist") -> NotExist | D191: =IFERROR(IF(B191>ROUNDUP(C191,0),"Elevated","Ok"),"New") -> New | E191: =VLOOKUP(A:A,Reviewed!B:C,2,0) -> #N/A | F191: =LEFT(A191,255)
C192: =IFERROR(ROUNDUP(VLOOKUP(F192,'30Days-Baseline'!C:D,2,FALSE),0),"NotExist") -> NotExist | D192: =IFERROR(IF(B192>ROUNDUP(C192,0),"Elevated","Ok"),"New") -> New | E192: =VLOOKUP(A:A,Reviewed!B:C,2,0) -> #N/A | F192: =LEFT(A192,255)
C193: =IFERROR(ROUNDUP(VLOOKUP(F193,'30Days-Baseline'!C:D,2,FALSE),0),"NotExist") -> NotExist | D193: =IFERROR(IF(B193>ROUNDUP(C193,0),"Elevated","Ok"),"New") -> New | E193: =VLOOKUP(A:A,Reviewed!B:C,2,0) -> #N/A | F193: =LEFT(A193,255)
C194: =IFERROR(ROUNDUP(VLOOKUP(F194,'30Days-Baseline'!C:D,2,FALSE),0),"NotExist") -> NotExist | D194: =IFERROR(IF(B194>ROUNDUP(C194,0),"Elevated","Ok"),"New") -> New | E194: =VLOOKUP(A:A,Reviewed!B:C,2,0) -> #N/A | F194: =LEFT(A194,255)
C195: =IFERROR(ROUNDUP(VLOOKUP(F195,'30Days-Baseline'!C:D,2,FALSE),0),"NotExist") -> NotExist | D195: =IFERROR(IF(B195>ROUNDUP(C195,0),"Elevated","Ok"),"New") -> New | E195: =VLOOKUP(A:A,Reviewed!B:C,2,0) -> #N/A | F195: =LEFT(A195,255)
C196: =IFERROR(ROUNDUP(VLOOKUP(F196,'30Days-Baseline'!C:D,2,FALSE),0),"NotExist") -> NotExist | D196: =IFERROR(IF(B196>ROUNDUP(C196,0),"Elevated","Ok"),"New") -> New | E196: =VLOOKUP(A:A,Reviewed!B:C,2,0) -> #N/A | F196: =LEFT(A196,255)
C197: =IFERROR(ROUNDUP(VLOOKUP(F197,'30Days-Baseline'!C:D,2,FALSE),0),"NotExist") -> NotExist | D197: =IFERROR(IF(B197>ROUNDUP(C197,0),"Elevated","Ok"),"New") -> New | E197: =VLOOKUP(A:A,Reviewed!B:C,2,0) -> #N/A | F197: =LEFT(A197,255)
... C2132: =IFERROR(ROUNDUP(VLOOKUP(F2132,'30Days-Baseline'!C:D,2,FALSE),0),"NotExist") -> NotExist | D2132: =IFERROR(IF(B2132>ROUNDUP(C2132,0),"Elevated","Ok"),"New") -> New | E2132: =VLOOKUP(A:A,Reviewed!B:C,2,0) -> #N/A | F2132: =LEFT(A2132,255)

Sheet 30Days-Baseline
A1: exception | B1: Count | C1: trim 255 for VLOOKUP | D1: Average(total/30 +30%)
A2: EMSG:-STRACE:-STRACERAW:com.guidewire.pc.domain.purge.PurgeHandlerImpl.doPurge(PurgeHandlerImpl.java:XXX | B2: 336316 | C2: =LEFT(A2,255) -> EMSG:-STRACE:-STRACERAW:com.guidewire.pc.domain.purge.PurgeHandlerImpl.doPurge(PurgeHandlerImpl.java:XXX | D2: =IF(AND((B2/10)<1,(B2/10)>0),1,(B2/10)*130%) -> 43721.08
A3: EMSG:-STRACE:-STRACERAW:com.farmers.edge.framework.exception.handler.imp.DefaultEdgeExceptionHandler.handleException(DefaultEdgeExceptionHandler.gs:XXX | B3: 37214 | C3: =LEFT(A3,255) -> EMSG:-STRACE:-STRACERAW:com.farmers.edge.framework.exception.handler.imp.DefaultEdgeExceptionHandler.handleException(DefaultEdgeExceptionHandler.gs:XXX | D3: =IF(AND((B3/10)<1,(B3/10)>0),1,(B3/10)*130%) -> 4837.82
A4: EMSG:-STRACE:-STRACERAW:com.guidewire.pl.system.transaction.ConnectionHandler.newDbException(ConnectionHandler.java:XXX | B4: 36100 | C4: =LEFT(A4,255) -> EMSG:-STRACE:-STRACERAW:com.guidewire.pl.system.transaction.ConnectionHandler.newDbException(ConnectionHandler.java:XXX | D4: =IF(AND((B4/10)<1,(B4/10)>0),1,(B4/10)*130%) -> 4693
A5: EMSG:-STRACE:-STRACERAW:com.guidewire.pl.system.entity.proxy.EffDatedBranchProxy.handleBranchChange(EffDatedBranchProxy.java:XXX | B5: 28267 | C5: =LEFT(A5,255) -> EMSG:-STRACE:-STRACERAW:com.guidewire.pl.system.entity.proxy.EffDatedBranchProxy.handleBranchChange(EffDatedBranchProxy.java:XXX | D5: =IF(AND((B5/10)<1,(B5/10)>0),1,(B5/10)*130%) -> 3674.71
A6: EMSG:-STRACE:-STRACERAW:com.guidewire.pl.system.transaction.TransactionManagerImpl.rethrowException(TransactionManagerImpl.java:XXX | B6: 22541 | C6: =LEFT(A6,255) -> EMSG:-STRACE:-STRACERAW:com.guidewire.pl.system.transaction.TransactionManagerImpl.rethrowException(TransactionManagerImpl.java:XXX | D6: =IF(AND((B6/10)<1,(B6/10)>0),1,(B6/10)*130%) -> 2930.33
A7: EMSG:Answer the eligibility questions in order to validate the quote. If the questions have been answeredSTRACE:com.farmers.config.quoteandbind.validatequote.AbstractValidateQuoteHandler.validate(AbstractValidateQuoteHandler.gs:XXXSTRACERAW:- | B7: 20046 | C7: =LEFT(A7,255) -> EMSG:Answer the eligibility questions in order to validate the quote. If the questions have been answeredSTRACE:com.farmers.config.quoteandbind.validatequote.AbstractValidateQuoteHandler.validate(AbstractValidateQuoteHandler.gs:XXXSTRACERAW:- | D7: =IF(AND((B7/10)<1,(B7/10)>0),1,(B7/10)*130%) -> 2605.98
A8: EMSG:-STRACE:-STRACERAW:gw.job.JobConditions.assertOkay(JobConditions.gs:XXX | B8: 15856 | C8: =LEFT(A8,255) -> EMSG:-STRACE:-STRACERAW:gw.job.JobConditions.assertOkay(JobConditions.gs:XXX | D8: =IF(AND((B8/10)<1,(B8/10)>0),1,(B8/10)*130%) -> 2061.28
A9: EMSG:-STRACE:-STRACERAW:com.farmers.config.pa.validator.BrightlineValidator.validateQuoteBrightlineRules(BrightlineValidator.gs:XXX | B9: 11840 | C9: =LEFT(A9,255) -> EMSG:-STRACE:-STRACERAW:com.farmers.config.pa.validator.BrightlineValidator.validateQuoteBrightlineRules(BrightlineValidator.gs:XXX | D9: =IF(AND((B9/10)<1,(B9/10)>0),1,(B9/10)*130%) -> 1539.2
A10: EMSG:EntityValidationExceptionSTRACE:edge.capabilities.quote.submission.quoting.util.SubmissionUnderwritingIssuesUtil.checkSideBySideProcessExceptions(SubmissionUnderwritingIssuesUtil.gs:XXXSTRACERAW:- | B10: 10123 | C10: =LEFT(A10,255) -> EMSG:EntityValidationExceptionSTRACE:edge.capabilities.quote.submission.quoting.util.SubmissionUnderwritingIssuesUtil.checkSideBySideProcessExceptions(SubmissionUnderwritingIssuesUtil.gs:XXXSTRACERAW:- | D10: =IF(AND((B10/10)<1,(B10/10)>0),1,(B10/10)*130%) -> 1315.99
A11: EMSG:PolicyPeriod:XXX = XXX/XXXSTRACE:deployment.pc.war//com.guidewire.pl.system.entity.proxy.EffDatedBranchProxy.checkBranchVersionMostRecent(EffDatedBranchProxy.java:XXXSTRACERAW:- | B11: 9537 | C11: =LEFT(A11,255) -> EMSG:PolicyPeriod:XXX = XXX/XXXSTRACE:deployment.pc.war//com.guidewire.pl.system.entity.proxy.EffDatedBranchProxy.checkBranchVersionMostRecent(EffDatedBranchProxy.java:XXXSTRACERAW:- | D11: =IF(AND((B11/10)<1,(B11/10)>0),1,(B11/10)*130%) -> 1239.81
A12: EMSG:Read timed outSTRACE:java.base/java.net.SocketInputStream.socketReadXXX(Native MethodSTRACERAW:- | B12: 8263 | C12: =LEFT(A12,255) -> EMSG:Read timed outSTRACE:java.base/java.net.SocketInputStream.socketReadXXX(Native MethodSTRACERAW:- | D12: =IF(AND((B12/10)<1,(B12/10)>0),1,(B12/10)*130%) -> 1074.19
A13: EMSG:XXX has exceeded the accident and/or violation threshold for eligibility in this program.STRACE:com.farmers.config.pa.validator.BrightlineValidator.validateQuoteBrightlineRules(BrightlineValidator.gs:XXXSTRACERAW:- | B13: 7989 | C13: =LEFT(A13,255) -> EMSG:XXX has exceeded the accident and/or violation threshold for eligibility in this program.STRACE:com.farmers.config.pa.validator.BrightlineValidator.validateQuoteBrightlineRules(BrightlineValidator.gs:XXXSTRACERAW:- | D13: =IF(AND((B13/10)<1,(B13/10)>0),1,(B13/10)*130%) -> 1038.57
... A2797: EMSG:For eligible contact Takesha Coleman credit score is null. Please make sure credit is orderedSTRACE:com.farmers.config.common.credit.CreditScoreHelper.populateRatingCreditDTO(CreditScoreHelper.gs:XXXSTRACERAW:- | B2797: 6 | C2797: =LEFT(A2797,255) -> EMSG:For eligible contact Takesha Coleman credit score is null. Please make sure credit is orderedSTRACE:com.farmers.config.common.credit.CreditScoreHelper.populateRatingCreditDTO(CreditScoreHelper.gs:XXXSTRACERAW:- | D2797: =IF(AND((B2797/10)<1,(B2797/10)>0),1,(B2797/10)*130%) -> 1
A2798: EMSG:HO Desirability Logger | B2798: Step XXX.XXX : RiskSegment is either nullSTRACE:-STRACERAW: | C2798: =LEFT(A2798,255) -> EMSG:HO Desirability Logger | D2798: =IF(AND((B2798/10)<1,(B2798/10)>0),1,(B2798/10)*130%) -> #VALUE!
A2799: EMSG:Homeowners Loss Of Use: The coverage term 'ALE Term' is required. Enter a value.STRACE:edge.capabilities.quote.submission.quoting.util.SubmissionUnderwritingIssuesUtil.checkSideBySideProcessExceptions(SubmissionUnderwritingIssuesUtil.gs:XXXSTRACERAW:- | B2799: 6 | C2799: =LEFT(A2799,255) -> EMSG:Homeowners Loss Of Use: The coverage term 'ALE Term' is required. Enter a value.STRACE:edge.capabilities.quote.submission.quoting.util.SubmissionUnderwritingIssuesUtil.checkSideBySideProcessExceptions(SubmissionUnderwritingIssuesUtil.gs:XXXSTRACERAW: | D2799: =IF(AND((B2799/10)<1,(B2799/10)>0),1,(B2799/10)*130%) -> 1
A2800: EMSG:Jeremy LopezSTRACE:com.farmers.config.pa.validator.BrightlineValidator.validateQuoteBrightlineRules(BrightlineValidator.gs:XXXSTRACERAW:- | B2800: 6 | C2800: =LEFT(A2800,255) -> EMSG:Jeremy LopezSTRACE:com.farmers.config.pa.validator.BrightlineValidator.validateQuoteBrightlineRules(BrightlineValidator.gs:XXXSTRACERAW:- | D2800: =IF(AND((B2800/10)<1,(B2800/10)>0),1,(B2800/10)*130%) -> 1
A2801: EMSG:Rideshare and Food Delivery Coverage: The coverage term 'Coverage is' is required. Enter a value.;STRACE:edge.capabilities.quote.submission.quoting.util.SubmissionUnderwritingIssuesUtil.checkVerifyRateExceptions(SubmissionUnderwritingIssuesUtil.gs:XXXSTRACERAW:- | B2801: 6 | C2801: =LEFT(A2801,255) -> EMSG:Rideshare and Food Delivery Coverage: The coverage term 'Coverage is' is required. Enter a value.;STRACE:edge.capabilities.quote.submission.quoting.util.SubmissionUnderwritingIssuesUtil.checkVerifyRateExceptions(SubmissionUnderwritingIssuesUtil.gs:XX | D2801: =IF(AND((B2801/10)<1,(B2801/10)>0),1,(B2801/10)*130%) -> 1
A2802: EMSG:Select XXX as the Primary Driver on at least one vehicle. Since the number of vehicles is greater than the number of driversSTRACE:least one vehicle. Since the number of vehicles is greater than the number of drivers, each driver must be a Primary Driver on at least one vehicle. Select EHRLAND HOLLINGSWORTH as the Primary Driver on at least one vehicle. Since the number of vehicles is greater than the number of drivers, each driver must be a Primary Driver on at least one vehicle. at com.farmers.lob.pa.driverassignment.DriverAssignment.validateData(DriverAssignment.gs:XXXSTRACERAW:- | B2802: 6 | C2802: =LEFT(A2802,255) -> EMSG:Select XXX as the Primary Driver on at least one vehicle. Since the number of vehicles is greater than the number of driversSTRACE:least one vehicle. Since the number of vehicles is greater than the number of drivers, each driver must be a Primary Dr | D2802: =IF(AND((B2802/10)<1,(B2802/10)>0),1,(B2802/10)*130%) -> 1
A2803: EMSG:There are no assigned drivers for vehicle(s) # XXXSTRACE:edge.capabilities.quote.submission.quoting.util.SubmissionUnderwritingIssuesUtil.checkSideBySideProcessExceptions(SubmissionUnderwritingIssuesUtil.gs:XXXSTRACERAW:- | B2803: 6 | C2803: =LEFT(A2803,255) -> EMSG:There are no assigned drivers for vehicle(s) # XXXSTRACE:edge.capabilities.quote.submission.quoting.util.SubmissionUnderwritingIssuesUtil.checkSideBySideProcessExceptions(SubmissionUnderwritingIssuesUtil.gs:XXXSTRACERAW:- | D2803: =IF(AND((B2803/10)<1,(B2803/10)>0),1,(B2803/10)*130%) -> 1
A2804: EMSG:Update the missing required field. Garaged ZIP Town for vehicle XXX HONDA ACCORD XXXD SPORT needs to be selected when Garaging location ZIP code is associated with multiple town names.;STRACE:edge.capabilities.quote.submission.quoting.util.SubmissionUnderwritingIssuesUtil.checkVerifyRateExceptions(SubmissionUnderwritingIssuesUtil.gs:XXXSTRACERAW:- | B2804: 6 | C2804: =LEFT(A2804,255) -> EMSG:Update the missing required field. Garaged ZIP Town for vehicle XXX HONDA ACCORD XXXD SPORT needs to be selected when Garaging location ZIP code is associated with multiple town names.;STRACE:edge.capabilities.quote.submission.quoting.util.Submission | D2804: =IF(AND((B2804/10)<1,(B2804/10)>0),1,(B2804/10)*130%) -> 1
A2805: EMSG:error:entity.xxxUI-ValidationERRORMessagexxxSTRACE:of XXX-XXX-XXXX;error:entity.Person.HomePhone/Correct the Phone Number. Phone Number should be a ten digit numerical value in the format of XXX-XXX-XXXX at deployment.pc.war//gw.api.validation.ValidationExceptionUtil.throwDisplayableValidationExceptionIfNecessary(ValidationExceptionUtil.java:XXXSTRACERAW:- | B2805: 6 | C2805: =LEFT(A2805,255) -> EMSG:error:entity.xxxUI-ValidationERRORMessagexxxSTRACE:of XXX-XXX-XXXX;error:entity.Person.HomePhone/Correct the Phone Number. Phone Number should be a ten digit numerical value in the format of XXX-XXX-XXXX at deployment.pc.war//gw.api.validation.Valid | D2805: =IF(AND((B2805/10)<1,(B2805/10)>0),1,(B2805/10)*130%) -> 1
A2806: EMSG:error:entity.xxxUI-ValidationERRORMessagexxxSTRACE:of XXX-XXX-XXXX;error:entity.PolicyPriNamedInsured.HomePhoneInternal/Correct the Phone Number. Phone Number should be a ten digit numerical value in the format of XXX-XXX-XXXX at deployment.pc.war//gw.api.validation.ValidationExceptionUtil.throwDisplayableValidationExceptionIfNecessary(ValidationExceptionUtil.java:XXXSTRACERAW:- | B2806: 6 | C2806: =LEFT(A2806,255) -> EMSG:error:entity.xxxUI-ValidationERRORMessagexxxSTRACE:of XXX-XXX-XXXX;error:entity.PolicyPriNamedInsured.HomePhoneInternal/Correct the Phone Number. Phone Number should be a ten digit numerical value in the format of XXX-XXX-XXXX at deployment.pc.war// | D2806: =IF(AND((B2806/10)<1,(B2806/10)>0),1,(B2806/10)*130%) -> 1
A2807: EMSG:, AOR=XXXSTRACE:gw.acc.luw.rules.LUWCascadeToFutureTermsProcessor.actOnChild(LUWCascadeToFutureTermsProcessor.gs:XXXSTRACERAW:- | B2807: 5 | C2807: =LEFT(A2807,255) -> EMSG:, AOR=XXXSTRACE:gw.acc.luw.rules.LUWCascadeToFutureTermsProcessor.actOnChild(LUWCascadeToFutureTermsProcessor.gs:XXXSTRACERAW:- | D2807: =IF(AND((B2807/10)<1,(B2807/10)>0),1,(B2807/10)*130%) -> 1
A2808: EMSG:DERECK DIAZSTRACE:com.farmers.config.pa.validator.BrightlineValidator.validateQuoteBrightlineRules(BrightlineValidator.gs:XXXSTRACERAW:- | B2808: 5 | C2808: =LEFT(A2808,255) -> EMSG:DERECK DIAZSTRACE:com.farmers.config.pa.validator.BrightlineValidator.validateQuoteBrightlineRules(BrightlineValidator.gs:XXXSTRACERAW:- | D2808: =IF(AND((B2808/10)<1,(B2808/10)>0),1,(B2808/10)*130%) -> 1
A2809: EMSG:Ineligible Condition - XXX% ITV required for monoline policies in this county;STRACE:edge.capabilities.quote.submission.quoting.util.SubmissionUnderwritingIssuesUtil.checkVerifyRateExceptions(SubmissionUnderwritingIssuesUtil.gs:XXXSTRACERAW:- | B2809: 5 | C2809: =LEFT(A2809,255) -> EMSG:Ineligible Condition - XXX% ITV required for monoline policies in this county;STRACE:edge.capabilities.quote.submission.quoting.util.SubmissionUnderwritingIssuesUtil.checkVerifyRateExceptions(SubmissionUnderwritingIssuesUtil.gs:XXXSTRACERAW:- | D2809: =IF(AND((B2809/10)<1,(B2809/10)>0),1,(B2809/10)*130%) -> 1
A2810: EMSG:A report shows that the XXXSTRACE:the XXX CHEVROLET CRUZE XXXD LT has been flagged as having Vehicle History activity. at edge.capabilities.quote.submission.quoting.util.SubmissionUnderwritingIssuesUtil.checkSideBySideProcessExceptions(SubmissionUnderwritingIssuesUtil.gs:XXXSTRACERAW:- | B2810: 4 | C2810: =LEFT(A2810,255) -> EMSG:A report shows that the XXXSTRACE:the XXX CHEVROLET CRUZE XXXD LT has been flagged as having Vehicle History activity. at edge.capabilities.quote.submission.quoting.util.SubmissionUnderwritingIssuesUtil.checkSideBySideProcessExceptions(SubmissionUn | D2810: =IF(AND((B2810/10)<1,(B2810/10)>0),1,(B2810/10)*130%) -> 1
... A2921: EMSG:class gw.lang.parser.EvaluationException cannot be cast to class edge.validation.EdgeValidationException (gw.lang.parser.EvaluationException is in unnamed module of loader 'deployment.pc.war' @XXXaffXXXbXXX; edge.validation.EdgeValidationException is in unnamed module of loader com.guidewire.pl.system.gosu.GosuPluginContainer @XXXSTRACE:edge.capabilities.policychange.GatewayPolicyChangeHandler$block_XXX_.invoke(GatewayPolicyChangeHandler.gs:XXXSTRACERAW:- | B2921: 3 | C2921: =LEFT(A2921,255) -> EMSG:class gw.lang.parser.EvaluationException cannot be cast to class edge.validation.EdgeValidationException (gw.lang.parser.EvaluationException is in unnamed module of loader 'deployment.pc.war' @XXXaffXXXbXXX; edge.validation.EdgeValidationException is | D2921: =IF(AND((B2921/10)<1,(B2921/10)>0),1,(B2921/10)*130%) -> 1
A2922: EMSG: | B2922: RiskSegment is either nullSTRACE:-STRACERAW: | C2922: =LEFT(A2922,255) -> EMSG: | D2922: =IF(AND((B2922/10)<1,(B2922/10)>0),1,(B2922/10)*130%) -> #VALUE!
A2923: EMSG:, AOR=XXXSTRACE:java.base/java.util.ArrayList.<init>(ArrayList.java:XXXSTRACERAW:- | B2923: 2 | C2923: =LEFT(A2923,255) -> EMSG:, AOR=XXXSTRACE:java.base/java.util.ArrayList.<init>(ArrayList.java:XXXSTRACERAW:- | D2923: =IF(AND((B2923/10)<1,(B2923/10)>0),1,(B2923/10)*130%) -> 1
A2924: EMSG:-STRACE:-STRACERAW:&amp; Watercraft | B2924: 2 | C2924: =LEFT(A2924,255) -> EMSG:-STRACE:-STRACERAW:&amp; Watercraft | D2924: =IF(AND((B2924/10)<1,(B2924/10)>0),1,(B2924/10)*130%) -> 1
A2925: EMSG:-STRACE:-STRACERAW:Feb XXX XXX:XXX:XXX PST XXX, MSG=Transaction Failed. Failed to parse response : Unrecognized token 'No': was expecting (JSON String, Number, Array, Object or token 'null', 'true' or 'false' | B2925: 2 | C2925: =LEFT(A2925,255) -> EMSG:-STRACE:-STRACERAW:Feb XXX XXX:XXX:XXX PST XXX, MSG=Transaction Failed. Failed to parse response : Unrecognized token 'No': was expecting (JSON String, Number, Array, Object or token 'null', 'true' or 'false' | D2925: =IF(AND((B2925/10)<1,(B2925/10)>0),1,(B2925/10)*130%) -> 1
A2926: EMSG:-STRACE:-STRACERAW:com.farmers.automation.gosuscript.gosuutil.GosuScriptUtil.retrieveGosuScriptUnProcessedRecords(GosuScriptUtil.gs:XXX | B2926: 2 | C2926: =LEFT(A2926,255) -> EMSG:-STRACE:-STRACERAW:com.farmers.automation.gosuscript.gosuutil.GosuScriptUtil.retrieveGosuScriptUnProcessedRecords(GosuScriptUtil.gs:XXX | D2926: =IF(AND((B2926/10)<1,(B2926/10)>0),1,(B2926/10)*130%) -> 1
A2927: EMSG:-STRACE:-STRACERAW:com.guidewire.pc.domain.job.impl.JobImpl.setSelectedVersion(JobImpl.java:XXX | B2927: 2 | C2927: =LEFT(A2927,255) -> EMSG:-STRACE:-STRACERAW:com.guidewire.pc.domain.job.impl.JobImpl.setSelectedVersion(JobImpl.java:XXX | D2927: =IF(AND((B2927/10)<1,(B2927/10)>0),1,(B2927/10)*130%) -> 1
A2928: EMSG:-STRACE:-STRACERAW:com.guidewire.pl.metadata.datatypeXXX.fieldvalidator.FieldValidatorInfo.validateFormat(FieldValidatorInfo.java:XXX | B2928: 2 | C2928: =LEFT(A2928,255) -> EMSG:-STRACE:-STRACERAW:com.guidewire.pl.metadata.datatypeXXX.fieldvalidator.FieldValidatorInfo.validateFormat(FieldValidatorInfo.java:XXX | D2928: =IF(AND((B2928/10)<1,(B2928/10)>0),1,(B2928/10)*130%) -> 1
A2929: EMSG:-STRACE:-STRACERAW:deployment.pc.war//com.guidewire.pc.domain.policy.period.impl.PolicyPeriodImpl.lockBranch(PolicyPeriodImpl.java:XXX | B2929: 2 | C2929: =LEFT(A2929,255) -> EMSG:-STRACE:-STRACERAW:deployment.pc.war//com.guidewire.pc.domain.policy.period.impl.PolicyPeriodImpl.lockBranch(PolicyPeriodImpl.java:XXX | D2929: =IF(AND((B2929/10)<1,(B2929/10)>0),1,(B2929/10)*130%) -> 1
A2930: EMSG:-STRACE:-STRACERAW:gw.plugin.preupdate.impl.DemoPreUpdateImpl.handleJobPreUpdate(DemoPreUpdateImpl.gs:XXX | B2930: 2 | C2930: =LEFT(A2930,255) -> EMSG:-STRACE:-STRACERAW:gw.plugin.preupdate.impl.DemoPreUpdateImpl.handleJobPreUpdate(DemoPreUpdateImpl.gs:XXX | D2930: =IF(AND((B2930/10)<1,(B2930/10)>0),1,(B2930/10)*130%) -> 1
A2931: EMSG:-STRACE:-STRACERAW:invoke (line: XXX, column: XXX | B2931: 2 | C2931: =LEFT(A2931,255) -> EMSG:-STRACE:-STRACERAW:invoke (line: XXX, column: XXX | D2931: =IF(AND((B2931/10)<1,(B2931/10)>0),1,(B2931/10)*130%) -> 1
A2932: EMSG:-STRACE:-STRACERAW:oracle.jdbc.driver.TXXXCMAREngineNIO.prepareForUnmarshall(TXXXCMAREngineNIO.java:XXX | B2932: 2 | C2932: =LEFT(A2932,255) -> EMSG:-STRACE:-STRACERAW:oracle.jdbc.driver.TXXXCMAREngineNIO.prepareForUnmarshall(TXXXCMAREngineNIO.java:XXX | D2932: =IF(AND((B2932/10)<1,(B2932/10)>0),1,(B2932/10)*130%) -> 1
A2933: EMSG:-STRACE:allows withdraw at gw.job.JobConditions.assertOkay(JobConditions.gs:XXXSTRACERAW:- | B2933: 2 | C2933: =LEFT(A2933,255) -> EMSG:-STRACE:allows withdraw at gw.job.JobConditions.assertOkay(JobConditions.gs:XXXSTRACERAW:- | D2933: =IF(AND((B2933/10)<1,(B2933/10)>0),1,(B2933/10)*130%) -> 1
...

Sheet Reviewed
A1: Exception | B1: TRIM | C1: Comments
A2: EMSG:- MSG:- STRACE1:deployment.pc.war//gw.api.webservice.workflow.WorkflowAPIImpl.resumeWorkflow | B2: =LEFT(A2,255) -> EMSG:- MSG:- STRACE1:deployment.pc.war//gw.api.webservice.workflow.WorkflowAPIImpl.resumeWorkflow | C2: Existing
A3: EMSG:- MSG:Business Content Population Failed STRACE1:- | B3: =LEFT(A3,255) -> EMSG:- MSG:Business Content Population Failed STRACE1:- | C3: Existing
A4: EMSG:There MSG:Failed to Quote Enhanced STRACE1:gw.job.QuoteProcess.requestQuote | B4: =LEFT(A4,255) -> EMSG:There MSG:Failed to Quote Enhanced STRACE1:gw.job.QuoteProcess.requestQuote | C4: Existing
A5: EMSG:- MSG:- STRACE1:com.guidewire.pl.system.cache.RarelyChangingBeanDataCache.ensureIsStarted | B5: =LEFT(A5,255) -> EMSG:- MSG:- STRACE1:com.guidewire.pl.system.cache.RarelyChangingBeanDataCache.ensureIsStarted | C5: Existing
A6: EMSG:- MSG:- STRACE1:com.guidewire.pl.system.workqueue.DistributedWorkerControllerImpl.checkOutWorkItems | B6: =LEFT(A6,255) -> EMSG:- MSG:- STRACE1:com.guidewire.pl.system.workqueue.DistributedWorkerControllerImpl.checkOutWorkItems | C6: Existing
A7: EMSG:- MSG:- STRACE1:com.farmers.config.pup.prefill.legacy.PUPULClientDetailsLoaderAndRefresher$block_24_.invoke | B7: =LEFT(A7,255) -> EMSG:- MSG:- STRACE1:com.farmers.config.pup.prefill.legacy.PUPULClientDetailsLoaderAndRefresher$block_24_.invoke | C7: Existing
A8: EMSG:There is no bi code in the table 'pa_pi_bi_codes' for 30000_65000 BI limits MSG:There STRACE1:com.farmers.tier.pa.pitier.impl.PITierCodesCalculatorImpl.calculateBILimitCode | B8: =LEFT(A8,255) -> EMSG:There is no bi code in the table 'pa_pi_bi_codes' for 30000_65000 BI limits MSG:There STRACE1:com.farmers.tier.pa.pitier.impl.PITierCodesCalculatorImpl.calculateBILimitCode | C8: Existing
A9: EMSG:There is no bi code in the table 'pa_pi_bi_codes' for 35000_80000 BI limits MSG:There STRACE1:com.farmers.tier.pa.pitier.impl.PITierCodesCalculatorImpl.calculateBILimitCode | B9: =LEFT(A9,255) -> EMSG:There is no bi code in the table 'pa_pi_bi_codes' for 35000_80000 BI limits MSG:There STRACE1:com.farmers.tier.pa.pitier.impl.PITierCodesCalculatorImpl.calculateBILimitCode | C9: Existing
A10: EMSG:\ MSG:Exception Occurred STRACE1:com.farmers.integ.framework.job.automatejob.AutomatedJob.executeJob | B10: =LEFT(A10,255) -> EMSG:\ MSG:Exception Occurred STRACE1:com.farmers.integ.framework.job.automatejob.AutomatedJob.executeJob | C10: Existing
A11: EMSG:\ MSG:AutomatedJob STRACE1:gw.lang.enhancements.CoreIterableEnhancement.partitionUniquely | B11: =LEFT(A11,255) -> EMSG:\ MSG:AutomatedJob STRACE1:gw.lang.enhancements.CoreIterableEnhancement.partitionUniquely | C11: Existing
A12: EMSG:- MSG:- STRACE1:com.guidewire.pl.system.integration.messaging.dispatch.MessagingHelperProxy$Operation.getDestinationNotOwnedResult | B12: =LEFT(A12,255) -> EMSG:- MSG:- STRACE1:com.guidewire.pl.system.integration.messaging.dispatch.MessagingHelperProxy$Operation.getDestinationNotOwnedResult | C12: Existing
A13: EMSG:- MSG:- STRACE1:[row,col {unknown-source}]: [205,27], while reading `payload` as Xml. [row,col]: [205,27]" evaluating expression: "%dw 2.0 output application/xml ns soapenv http://schemas.xmlsoap.org/soap/envelope/ --- | B13: =LEFT(A13,255) -> EMSG:- MSG:- STRACE1:[row,col {unknown-source}]: [205,27], while reading `payload` as Xml. [row,col]: [205,27]" evaluating expression: "%dw 2.0 output application/xml ns soapenv http://schemas.xmlsoap.org/soap/envelope/ --- | C13: Existing
... A31: EMSG:class entity.RelatedPolicyDetail_Ext cannot be cast to class entity.MDMPolicyDetail_Ext (entity.RelatedPolicyDetail_Ext and entity.MDMPolicyDetail_Ext are in unnamed module of loader 'deployment.pc.war' @5fb4994e) MSG:Exception STRACE1:com.farmers.contingencies.enhancements.PolicyPeriodContingencyEnhancement$block_11_.invoke | B31: =LEFT(A31,255) -> EMSG:class entity.RelatedPolicyDetail_Ext cannot be cast to class entity.MDMPolicyDetail_Ext (entity.RelatedPolicyDetail_Ext and entity.MDMPolicyDetail_Ext are in unnamed module of loader 'deployment.pc.war' @5fb4994e) MSG:Exception STRACE1:com.farmers.co | C31: New
